---
title: "C2707 błąd kompilatora | Dokumentacja firmy Microsoft"
ms.custom: 
ms.date: 11/04/2016
ms.reviewer: 
ms.suite: 
ms.technology:
- cpp-tools
ms.tgt_pltfrm: 
ms.topic: error-reference
f1_keywords:
- C2707
dev_langs:
- C++
helpviewer_keywords:
- C2707
ms.assetid: 3deaf45c-74da-4c9d-acc6-b82412720b74
caps.latest.revision: 
author: corob-msft
ms.author: corob
manager: ghogen
ms.workload:
- cplusplus
ms.openlocfilehash: 877ca1b0592625823e262f77f7f2adcfc5c04e3e
ms.sourcegitcommit: 8fa8fdf0fbb4f57950f1e8f4f9b81b4d39ec7d7a
ms.translationtype: MT
ms.contentlocale: pl-PL
ms.lasthandoff: 12/21/2017
---
# <a name="compiler-error-c2707"></a>C2707 błąd kompilatora
'Identyfikator': zły kontekst dla wewnętrznej funkcji  
  
 Strukturalne obsługi wyjątków funkcje wewnętrzne są nieprawidłowe w niektórych kontekstach:  
  
-   `_exception_code()`poza filtrem wyjątków lub `__except` bloku  
  
-   `_exception_info()`poza filtrem wyjątków  
  
-   `_abnormal_termination()`poza `__finally` bloku  
  
 Aby rozwiązać problem, można znajdują się w kontekście odpowiednie funkcje wewnętrzne obsługi wyjątków.  
  
## <a name="example"></a>Przykład  
 Poniższy przykład generuje C2707.  
  
```  
// C2707.cpp  
#include <windows.h>  
#include <stdio.h>  
  
LONG MyFilter(LONG excode)   
{  
    return (excode == EXCEPTION_ACCESS_VIOLATION ?  
        EXCEPTION_EXECUTE_HANDLER : EXCEPTION_CONTINUE_SEARCH);   // OK  
}  
  
LONG func(void)   
{  
    int x, y;  
    return(GetExceptionCode() == EXCEPTION_ACCESS_VIOLATION ?  // C2707  
             EXCEPTION_EXECUTE_HANDLER : EXCEPTION_CONTINUE_SEARCH);  
  
    __try   
    {  
        y = 0;  
        x = 4 / y;  
        return 0;  
     }  
  
    __except(MyFilter(GetExceptionCode()))   
    {  
        return(GetExceptionCode() == EXCEPTION_ACCESS_VIOLATION ? // ok  
               EXCEPTION_EXECUTE_HANDLER : EXCEPTION_CONTINUE_SEARCH);  
    }  
}  
  
int main()   
{  
    __try   
    {  
        func();  
    } __except(EXCEPTION_EXECUTE_HANDLER)  
    {  
        printf_s("Caught exception\n");  
    }  
}  
```